Workbook

Sheet Exported Results
A1: Block Type | B1: 384-Well Block
A2: Calibration Background is expired | B2: No
A3: Calibration Background performed on | B3: 01-13-2022
A4: Calibration Normalization FAM-ROX is expired | B4: No
A5: Calibration Normalization FAM-ROX performed on | B5: 10-06-2021
A6: Calibration Normalization VIC-ROX is expired | B6: No
A7: Calibration Normalization VIC-ROX performed on | B7: 10-06-2021
A8: Calibration Pure Dye FAM is expired | B8: No
A9: Calibration Pure Dye FAM performed on | B9: 10-06-2021
A10: Calibration Pure Dye NED is expired | B10: No
A11: Calibration Pure Dye NED performed on | B11: 10-06-2021
A12: Calibration Pure Dye ROX is expired | B12: No
... A25: Date Created | B25: 2022-02-24 11:46:50 AM GMT
A26: Experiment Barcode
A27: Experiment Comment
A28: Experiment File Name | B28: D:\Users\Administrator\Desktop\FELIX\Felix OPLA vs POLA 2.eds
A29: Experiment Name | B29: Felix OPLA vs POLA 2
A30: Experiment Run End Time | B30: 2022-02-24 12:45:21 PM GMT
A31: Experiment Type | B31: Standard Curve
A32: Instrument Name | B32: HotPants
A33: Instrument Serial Number | B33: 278871706
A34: Instrument Type | B34: QuantStudio(TM) 7 Flex System
A35: Passive Reference | B35: ROX
A36: Quantification Cycle Method | B36: Ct
A37: Signal Smoothing On | B37: true
A38: Stage/ Cycle where Analysis is performed | B38: Stage 2, Step 2
A39: User Name
A41: Well Position | B41: Sample Name | C41: Target Name | D41: CT | H41: Sample Name
A42: A1 | B42: Blank 1.a | C42: LC3 | D42: Undetermined | H42: Blank 1.a
A43: A2 | B43: Blank 1.b | C43: LC3 | D43: Undetermined | H43: Blank 1.b
A44: A3 | B44: Blank 1.c | C44: LC3 | D44: Undetermined | H44: Blank 1.c
A45: A4 | B45: STD 10a | C45: LC3 | D45: 32.110306 | H45: STD 10a
A46: A5 | B46: STD 10b | C46: LC3 | D46: 32.416737 | H46: STD 10b
A47: A6 | B47: STD 10c | C47: LC3 | D47: 32.284096 | H47: STD 10c
A48: A7 | B48: STD 20a | C48: LC3 | D48: 34.321381 | H48: STD 20a
A49: A8 | B49: STD 20b | C49: LC3 | D49: 33.354897 | H49: STD 20b
A50: A9 | B50: STD 20c | C50: LC3 | D50: 33.332657 | H50: STD 20c
A51: A10 | B51: STD 40a | C51: LC3 | D51: 35.167088 | H51: STD 40a
A52: A11 | B52: STD 40b | C52: LC3 | D52: 34.975227 | H52: STD 40b
A53: A12 | B53: STD 40c | C53: LC3 | D53: 34.643658 | H53: STD 40c
...

Sheet Results Workspace
A2: Well | B2: Ct from reader | C2: Corrected Cts | D2: Sample Name | E2: Average Ct | F2: STDEV
A3: A1 | B3: =VLOOKUP(A3,'Exported Results'!A$42:D$161,4,FALSE) -> Undetermined | C3: =IF(B3="Undetermined",40.1,B3) -> 40.1 | D3: =VLOOKUP(A3,'Exported Results'!A$42:D$161,2,FALSE) -> Blank 1.a | E3: =AVERAGE(C3:C5) -> 40.1 | F3: =_xlfn.STDEV.P(C3:C5) -> 0
A4: A2 | B4: =VLOOKUP(A4,'Exported Results'!A$42:D$161,4,FALSE) -> Undetermined | C4: =IF(B4="Undetermined",40.1,B4) -> 40.1 | D4: =VLOOKUP(A4,'Exported Results'!A$42:D$161,2,FALSE) -> Blank 1.b
A5: A3 | B5: =VLOOKUP(A5,'Exported Results'!A$42:D$161,4,FALSE) -> Undetermined | C5: =IF(B5="Undetermined",40.1,B5) -> 40.1 | D5: =VLOOKUP(A5,'Exported Results'!A$42:D$161,2,FALSE) -> Blank 1.c
A6: A4 | B6: =VLOOKUP(A6,'Exported Results'!A$42:D$161,4,FALSE) -> 32.110306 | C6: =IF(B6="Undetermined",40.1,B6) -> 32.110306 | D6: =VLOOKUP(A6,'Exported Results'!A$42:D$161,2,FALSE) -> STD 10a | E6: =AVERAGE(C6:C8) -> 32.270379 | F6: =_xlfn.STDEV.P(C6:C8) -> 0.12547527
A7: A5 | B7: =VLOOKUP(A7,'Exported Results'!A$42:D$161,4,FALSE) -> 32.416737 | C7: =IF(B7="Undetermined",40.1,B7) -> 32.416737 | D7: =VLOOKUP(A7,'Exported Results'!A$42:D$161,2,FALSE) -> STD 10b
A8: A6 | B8: =VLOOKUP(A8,'Exported Results'!A$42:D$161,4,FALSE) -> 32.284096 | C8: =IF(B8="Undetermined",40.1,B8) -> 32.284096 | D8: =VLOOKUP(A8,'Exported Results'!A$42:D$161,2,FALSE) -> STD 10c
A9: A7 | B9: =VLOOKUP(A9,'Exported Results'!A$42:D$161,4,FALSE) -> 34.321381 | D9: =VLOOKUP(A9,'Exported Results'!A$42:D$161,2,FALSE) -> STD 20a | E9: =AVERAGE(C9:C11) -> 33.343777 | F9: =_xlfn.STDEV.P(C9:C11) -> 0.011119843
A10: A8 | B10: =VLOOKUP(A10,'Exported Results'!A$42:D$161,4,FALSE) -> 33.354897 | C10: =IF(B10="Undetermined",40.1,B10) -> 33.354897 | D10: =VLOOKUP(A10,'Exported Results'!A$42:D$161,2,FALSE) -> STD 20b
A11: A9 | B11: =VLOOKUP(A11,'Exported Results'!A$42:D$161,4,FALSE) -> 33.332657 | C11: =IF(B11="Undetermined",40.1,B11) -> 33.332657 | D11: =VLOOKUP(A11,'Exported Results'!A$42:D$161,2,FALSE) -> STD 20c
A12: A10 | B12: =VLOOKUP(A12,'Exported Results'!A$42:D$161,4,FALSE) -> 35.167088 | C12: =IF(B12="Undetermined",40.1,B12) -> 35.167088 | D12: =VLOOKUP(A12,'Exported Results'!A$42:D$161,2,FALSE) -> STD 40a | E12: =AVERAGE(C12:C14) -> 35.071157 | F12: =_xlfn.STDEV.P(C12:C14) -> 0.095930099
A13: A11 | B13: =VLOOKUP(A13,'Exported Results'!A$42:D$161,4,FALSE) -> 34.975227 | C13: =IF(B13="Undetermined",40.1,B13) -> 34.975227 | D13: =VLOOKUP(A13,'Exported Results'!A$42:D$161,2,FALSE) -> STD 40b
A14: A12 | B14: =VLOOKUP(A14,'Exported Results'!A$42:D$161,4,FALSE) -> 34.643658 | D14: =VLOOKUP(A14,'Exported Results'!A$42:D$161,2,FALSE) -> STD 40c
A15: A13 | B15: =VLOOKUP(A15,'Exported Results'!A$42:D$161,4,FALSE) -> 36.926029 | C15: =IF(B15="Undetermined",40.1,B15) -> 36.926029 | D15: =VLOOKUP(A15,'Exported Results'!A$42:D$161,2,FALSE) -> STD 80a | E15: =AVERAGE(C15:C17) -> 36.079328 | F15: =_xlfn.STDEV.P(C15:C17) -> 0.65005509
A16: A14 | B16: =VLOOKUP(A16,'Exported Results'!A$42:D$161,4,FALSE) -> 35.966106 | C16: =IF(B16="Undetermined",40.1,B16) -> 35.966106 | D16: =VLOOKUP(A16,'Exported Results'!A$42:D$161,2,FALSE) -> STD 80b
A17: A15 | B17: =VLOOKUP(A17,'Exported Results'!A$42:D$161,4,FALSE) -> 35.345848 | C17: =IF(B17="Undetermined",40.1,B17) -> 35.345848 | D17: =VLOOKUP(A17,'Exported Results'!A$42:D$161,2,FALSE) -> STD 80c
A18: A16 | B18: =VLOOKUP(A18,'Exported Results'!A$42:D$161,4,FALSE) -> 36.320671 | C18: =IF(B18="Undetermined",40.1,B18) -> 36.320671 | D18: =VLOOKUP(A18,'Exported Results'!A$42:D$161,2,FALSE) -> STD 160a | E18: =AVERAGE(C18:C20) -> 36.016375 | F18: =_xlfn.STDEV.P(C18:C20) -> 0.30429649
A19: A17 | B19: =VLOOKUP(A19,'Exported Results'!A$42:D$161,4,FALSE) -> 38.275249 | D19: =VLOOKUP(A19,'Exported Results'!A$42:D$161,2,FALSE) -> STD 160b
A20: A18 | B20: =VLOOKUP(A20,'Exported Results'!A$42:D$161,4,FALSE) -> 35.712078 | C20: =IF(B20="Undetermined",40.1,B20) -> 35.712078 | D20: =VLOOKUP(A20,'Exported Results'!A$42:D$161,2,FALSE) -> STD 160c
A21: A19 | B21: =VLOOKUP(A21,'Exported Results'!A$42:D$161,4,FALSE) -> 37.8685 | C21: =IF(B21="Undetermined",40.1,B21) -> 37.8685 | D21: =VLOOKUP(A21,'Exported Results'!A$42:D$161,2,FALSE) -> STD 320a | E21: =AVERAGE(C21:C23) -> 37.220501 | F21: =_xlfn.STDEV.P(C21:C23) -> 0.64799881
A22: A20 | B22: =VLOOKUP(A22,'Exported Results'!A$42:D$161,4,FALSE) -> 36.572502 | C22: =IF(B22="Undetermined",40.1,B22) -> 36.572502 | D22: =VLOOKUP(A22,'Exported Results'!A$42:D$161,2,FALSE) -> STD 320b
A23: A21 | B23: =VLOOKUP(A23,'Exported Results'!A$42:D$161,4,FALSE) -> Undetermined | D23: =VLOOKUP(A23,'Exported Results'!A$42:D$161,2,FALSE) -> STD 320c
A24: A22 | B24: =VLOOKUP(A24,'Exported Results'!A$42:D$161,4,FALSE) -> 34.839085 | C24: =IF(B24="Undetermined",40.1,B24) -> 34.839085 | D24: =VLOOKUP(A24,'Exported Results'!A$42:D$161,2,FALSE) -> C1.a | E24: =AVERAGE(C24:C26) -> 35.532425 | F24: =_xlfn.STDEV.P(C24:C26) -> 0.56129445
A25: A23 | B25: =VLOOKUP(A25,'Exported Results'!A$42:D$161,4,FALSE) -> 35.544376 | C25: =IF(B25="Undetermined",40.1,B25) -> 35.544376 | D25: =VLOOKUP(A25,'Exported Results'!A$42:D$161,2,FALSE) -> C1.b
A26: A24 | B26: =VLOOKUP(A26,'Exported Results'!A$42:D$161,4,FALSE) -> 36.213814 | C26: =IF(B26="Undetermined",40.1,B26) -> 36.213814 | D26: =VLOOKUP(A26,'Exported Results'!A$42:D$161,2,FALSE) -> C1.c
A27: B1 | B27: =VLOOKUP(A27,'Exported Results'!A$42:D$161,4,FALSE) -> 37.894287 | D27: =VLOOKUP(A27,'Exported Results'!A$42:D$161,2,FALSE) -> C2.a | E27: =AVERAGE(C27:C29) -> 34.937532 | F27: =_xlfn.STDEV.P(C27:C29) -> 0.31530952
A28: B2 | B28: =VLOOKUP(A28,'Exported Results'!A$42:D$161,4,FALSE) -> 35.252842 | C28: =IF(B28="Undetermined",40.1,B28) -> 35.252842 | D28: =VLOOKUP(A28,'Exported Results'!A$42:D$161,2,FALSE) -> C2.b
A29: B3 | B29: =VLOOKUP(A29,'Exported Results'!A$42:D$161,4,FALSE) -> 34.622223 | C29: =IF(B29="Undetermined",40.1,B29) -> 34.622223 | D29: =VLOOKUP(A29,'Exported Results'!A$42:D$161,2,FALSE) -> C2.c
A30: B4 | B30: =VLOOKUP(A30,'Exported Results'!A$42:D$161,4,FALSE) -> 34.066959 | D30: =VLOOKUP(A30,'Exported Results'!A$42:D$161,2,FALSE) -> C3.a | E30: =AVERAGE(C30:C32) -> 35.105301 | F30: =_xlfn.STDEV.P(C30:C32) -> 0.24104309
A31: B5 | B31: =VLOOKUP(A31,'Exported Results'!A$42:D$161,4,FALSE) -> 35.346344 | C31: =IF(B31="Undetermined",40.1,B31) -> 35.346344 | D31: =VLOOKUP(A31,'Exported Results'!A$42:D$161,2,FALSE) -> C3.b
A32: B6 | B32: =VLOOKUP(A32,'Exported Results'!A$42:D$161,4,FALSE) -> 34.864258 | C32: =IF(B32="Undetermined",40.1,B32) -> 34.864258 | D32: =VLOOKUP(A32,'Exported Results'!A$42:D$161,2,FALSE) -> C3.c
A33: B7 | B33: =VLOOKUP(A33,'Exported Results'!A$42:D$161,4,FALSE) -> 34.565525 | C33: =IF(B33="Undetermined",40.1,B33) -> 34.565525 | D33: =VLOOKUP(A33,'Exported Results'!A$42:D$161,2,FALSE) -> C4.a | E33: =AVERAGE(C33:C35) -> 34.758829 | F33: =_xlfn.STDEV.P(C33:C35) -> 0.19330406
A34: B8 | B34: =VLOOKUP(A34,'Exported Results'!A$42:D$161,4,FALSE) -> 35.762131 | D34: =VLOOKUP(A34,'Exported Results'!A$42:D$161,2,FALSE) -> C4.b
A35: B9 | B35: =VLOOKUP(A35,'Exported Results'!A$42:D$161,4,FALSE) -> 34.952133 | C35: =IF(B35="Undetermined",40.1,B35) -> 34.952133 | D35: =VLOOKUP(A35,'Exported Results'!A$42:D$161,2,FALSE) -> C4.c
A36: B10 | B36: =VLOOKUP(A36,'Exported Results'!A$42:D$161,4,FALSE) -> 35.16143 | C36: =IF(B36="Undetermined",40.1,B36) -> 35.16143 | D36: =VLOOKUP(A36,'Exported Results'!A$42:D$161,2,FALSE) -> C5.a | E36: =AVERAGE(C36:C38) -> 34.734581 | F36: =_xlfn.STDEV.P(C36:C38) -> 0.30491777
A37: B11 | B37: =VLOOKUP(A37,'Exported Results'!A$42:D$161,4,FALSE) -> 34.468128 | C37: =IF(B37="Undetermined",40.1,B37) -> 34.468128 | D37: =VLOOKUP(A37,'Exported Results'!A$42:D$161,2,FALSE) -> C5.b
A38: B12 | B38: =VLOOKUP(A38,'Exported Results'!A$42:D$161,4,FALSE) -> 34.574184 | C38: =IF(B38="Undetermined",40.1,B38) -> 34.574184 | D38: =VLOOKUP(A38,'Exported Results'!A$42:D$161,2,FALSE) -> C5.c
A39: B13 | B39: =VLOOKUP(A39,'Exported Results'!A$42:D$161,4,FALSE) -> 35.205597 | C39: =IF(B39="Undetermined",40.1,B39) -> 35.205597 | D39: =VLOOKUP(A39,'Exported Results'!A$42:D$161,2,FALSE) -> C6.a | E39: =AVERAGE(C39:C41) -> 34.897055 | F39: =_xlfn.STDEV.P(C39:C41) -> 0.27967394
A40: B14 | B40: =VLOOKUP(A40,'Exported Results'!A$42:D$161,4,FALSE) -> 34.528477 | C40: =IF(B40="Undetermined",40.1,B40) -> 34.528477 | D40: =VLOOKUP(A40,'Exported Results'!A$42:D$161,2,FALSE) -> C6.b
A41: B15 | B41: =VLOOKUP(A41,'Exported Results'!A$42:D$161,4,FALSE) -> 34.957092 | C41: =IF(B41="Undetermined",40.1,B41) -> 34.957092 | D41: =VLOOKUP(A41,'Exported Results'!A$42:D$161,2,FALSE) -> C6.c
...

Sheet LC3
A1: Standard dilution | B1: Av CT | C1: SD CT | D1: CV CT | E1: Dilution | F1: log dilution
A2: =B33 -> STD 10a | B2: =C33 -> 32.270379 | C2: =D33 -> 0.12547527 | D2: =C2/B2 -> 0.003888249 | E2: 0.1 | F2: =LOG(E2,10) -> -1
A3: =B34 -> STD 20a | B3: =C34 -> 33.343777 | C3: =D34 -> 0.011119843 | D3: =C3/B3 -> 0.00033349079 | E3: 0.05 | F3: =LOG(E3,10) -> -1.30103
A4: =B35 -> STD 40a | B4: =C35 -> 35.071157 | C4: =D35 -> 0.095930099 | D4: =C4/B4 -> 0.0027352989 | E4: 0.025 | F4: =LOG(E4,10) -> -1.60206
A5: =B36 -> STD 80a | B5: =C36 -> 36.079328 | C5: =D36 -> 0.65005509 | D5: =C5/B5 -> 0.018017383 | E5: 0.0125 | F5: =LOG(E5,10) -> -1.90309
A6: =B37 -> STD 160a | B6: =C37 -> 36.016375 | C6: =D37 -> 0.30429649 | D6: =C6/B6 -> 0.0084488374 | E6: 0.00625 | F6: =LOG(E6,10) -> -2.20412
A7: =B38 -> STD 320a | B7: =C38 -> 37.220501 | C7: =D38 -> 0.64799881 | D7: =C7/B7 -> 0.017409728 | E7: 0.003125 | F7: =LOG(E7,10) -> -2.50515
B28: Slope | C28: =SLOPE(B2:B7,F2:F7) -> -3.2058098
B29: Efficiency | C29: =10^(-1/C28) -> 2.0508489
B31: Sample | C31: Av Ct | D31: SD Ct | E31: CV Ct | F31: delta Ct (to STD 20) | G31: deltadelta Ct
B32: ='Results Workspace'!D3 -> Blank 1.a | C32: ='Results Workspace'!E3 -> 40.1 | D32: ='Results Workspace'!F3 -> 0 | E32: =D32/C32 -> 0 | F32: =$C$29^($B$3-C32) -> 0.0078074014
B33: ='Results Workspace'!D6 -> STD 10a | C33: ='Results Workspace'!E6 -> 32.270379 | D33: ='Results Workspace'!F6 -> 0.12547527 | E33: =D33/C33 -> 0.003888249 | F33: =$C$29^($B$3-C33) -> 2.1618659
B34: ='Results Workspace'!D9 -> STD 20a | C34: ='Results Workspace'!E9 -> 33.343777 | D34: ='Results Workspace'!F9 -> 0.011119843 | E34: =D34/C34 -> 0.00033349079 | F34: =$C$29^($B$3-C34) -> 1
B35: ='Results Workspace'!D12 -> STD 40a | C35: ='Results Workspace'!E12 -> 35.071157 | D35: ='Results Workspace'!F12 -> 0.095930099 | E35: =D35/C35 -> 0.0027352989 | F35: =$C$29^($B$3-C35) -> 0.28918236
B36: ='Results Workspace'!D15 -> STD 80a | C36: ='Results Workspace'!E15 -> 36.079328 | D36: ='Results Workspace'!F15 -> 0.65005509 | E36: =D36/C36 -> 0.018017383 | F36: =$C$29^($B$3-C36) -> 0.14018111
B37: ='Results Workspace'!D18 -> STD 160a | C37: ='Results Workspace'!E18 -> 36.016375 | D37: ='Results Workspace'!F18 -> 0.30429649 | E37: =D37/C37 -> 0.0084488374 | F37: =$C$29^($B$3-C37) -> 0.14666509
B38: ='Results Workspace'!D21 -> STD 320a | C38: ='Results Workspace'!E21 -> 37.220501 | D38: ='Results Workspace'!F21 -> 0.64799881 | E38: =D38/C38 -> 0.017409728 | F38: =$C$29^($B$3-C38) -> 0.061761694
B39: ='Results Workspace'!D24 -> C1.a | C39: ='Results Workspace'!E24 -> 35.532425 | D39: ='Results Workspace'!F24 -> 0.56129445 | E39: =D39/C39 -> 0.015796683 | F39: =$C$29^($B$3-C39) -> 0.20762849 | G39: =F39/'Housekeeper summary'!$E$4 -> 0.46080023
B40: ='Results Workspace'!D27 -> C2.a | C40: ='Results Workspace'!E27 -> 34.937532 | D40: ='Results Workspace'!F27 -> 0.31530952 | E40: =D40/C40 -> 0.0090249512 | F40: =$C$29^($B$3-C40) -> 0.31831268 | G40: =F40/'Housekeeper summary'!$E$4 -> 0.70644716
B41: ='Results Workspace'!D30 -> C3.a | C41: ='Results Workspace'!E30 -> 35.105301 | D41: ='Results Workspace'!F30 -> 0.24104309 | E41: =D41/C41 -> 0.0068662876 | F41: =$C$29^($B$3-C41) -> 0.2821768 | G41: =F41/'Housekeeper summary'!$E$4 -> 0.626249
B42: ='Results Workspace'!D33 -> C4.a | C42: ='Results Workspace'!E33 -> 34.758829 | D42: ='Results Workspace'!F33 -> 0.19330406 | E42: =D42/C42 -> 0.0055612938 | F42: =$C$29^($B$3-C42) -> 0.36190744 | G42: =F42/'Housekeeper summary'!$E$4 -> 0.80319919
B43: ='Results Workspace'!D36 -> C5.a | C43: ='Results Workspace'!E36 -> 34.734581 | D43: ='Results Workspace'!F36 -> 0.30491777 | E43: =D43/C43 -> 0.0087785071 | F43: =$C$29^($B$3-C43) -> 0.36826574 | G43: =F43/'Housekeeper summary'!$E$4 -> 0.81731048
B44: ='Results Workspace'!D39 -> C6.a | C44: ='Results Workspace'!E39 -> 34.897055 | D44: ='Results Workspace'!F39 -> 0.27967394 | E44: =D44/C44 -> 0.0080142563 | F44: =$C$29^($B$3-C44) -> 0.32770277 | G44: =F44/'Housekeeper summary'!$E$4 -> 0.72728705
B45: ='Results Workspace'!D42 -> C7.a | C45: ='Results Workspace'!E42 -> 33.999233 | D45: ='Results Workspace'!F42 -> 0.092967987 | E45: =D45/C45 -> 0.0027344142 | F45: =$C$29^($B$3-C45) -> 0.62451236 | G45: =F45/'Housekeeper summary'!$E$4 -> 1.3860113
B46: ='Results Workspace'!D45 -> C8.a | C46: ='Results Workspace'!E45 -> 34.287828 | D46: ='Results Workspace'!F45 -> 0.77317812 | E46: =D46/C46 -> 0.022549638 | F46: =$C$29^($B$3-C46) -> 0.50759657 | G46: =F46/'Housekeeper summary'!$E$4 -> 1.1265343
B47: ='Results Workspace'!D48 -> C9.a | C47: ='Results Workspace'!E48 -> 34.247986 | D47: ='Results Workspace'!F48 -> 0.089954376 | E47: =D47/C47 -> 0.0026265596 | F47: =$C$29^($B$3-C47) -> 0.52233212 | G47: =F47/'Housekeeper summary'!$E$4 -> 1.1592376
B48: ='Results Workspace'!D51 -> O1.a | C48: ='Results Workspace'!E51 -> 34.976986 | D48: ='Results Workspace'!F51 -> 0.34854649 | E48: =D48/C48 -> 0.0099650236 | F48: =$C$29^($B$3-C48) -> 0.30941906 | G48: =F48/'Housekeeper summary'!$E$4 -> 0.6867091
B49: ='Results Workspace'!D54 -> O2.a | C49: ='Results Workspace'!E54 -> 34.805933 | D49: ='Results Workspace'!F54 -> 0.046888351 | E49: =D49/C49 -> 0.0013471367 | F49: =$C$29^($B$3-C49) -> 0.34986801 | G49: =F49/'Housekeeper summary'!$E$4 -> 0.77647946
B50: ='Results Workspace'!D57 -> O3.a | C50: ='Results Workspace'!E57 -> 35.699053 | D50: ='Results Workspace'!F57 -> 0.34663974 | E50: =D50/C50 -> 0.009710054 | F50: =$C$29^($B$3-C50) -> 0.1842086 | G50: =F50/'Housekeeper summary'!$E$4 -> 0.4088233
B51: ='Results Workspace'!D60 -> O4.a | C51: ='Results Workspace'!E60 -> 34.948869 | D51: ='Results Workspace'!F60 -> 0.054155126 | E51: =D51/C51 -> 0.001549553 | F51: =$C$29^($B$3-C51) -> 0.31573131 | G51: =F51/'Housekeeper summary'!$E$4 -> 0.7007182
B52: ='Results Workspace'!D63 -> O5.a | C52: ='Results Workspace'!E63 -> 35.517793 | D52: ='Results Workspace'!F63 -> 0.36742902 | E52: =D52/C52 -> 0.010344928 | F52: =$C$29^($B$3-C52) -> 0.20982205 | G52: =F52/'Housekeeper summary'!$E$4 -> 0.46566851
B53: ='Results Workspace'!D66 -> O6.a | C53: ='Results Workspace'!E66 -> 35.542159 | D53: ='Results Workspace'!F66 -> 0.36314546 | E53: =D53/C53 -> 0.010217316 | F53: =$C$29^($B$3-C53) -> 0.20618194 | G53: =F53/'Housekeeper summary'!$E$4 -> 0.45758984
B54: ='Results Workspace'!D69 -> O7.a | C54: ='Results Workspace'!E69 -> 35.389189 | D54: ='Results Workspace'!F69 -> 0.32066706 | E54: =D54/C54 -> 0.0090611585 | F54: =$C$29^($B$3-C54) -> 0.23012665 | G54: =F54/'Housekeeper summary'!$E$4 -> 0.51073152
B55: ='Results Workspace'!D72 -> O8.a | C55: ='Results Workspace'!E72 -> 34.913682 | D55: ='Results Workspace'!F72 -> 0.2407516 | E55: =D55/C55 -> 0.0068956233 | F55: =$C$29^($B$3-C55) -> 0.32381249 | G55: =F55/'Housekeeper summary'!$E$4 -> 0.71865316
B56: ='Results Workspace'!D75 -> O9.a | C56: ='Results Workspace'!E75 -> 35.288603 | D56: ='Results Workspace'!F75 -> 0.27618086 | E56: =D56/C56 -> 0.0078263472 | F56: =$C$29^($B$3-C56) -> 0.24736774 | G56: =F56/'Housekeeper summary'!$E$4 -> 0.54899553
B57: ='Results Workspace'!D78 -> P1.a | C57: ='Results Workspace'!E78 -> 35.159084 | D57: ='Results Workspace'!F78 -> 0.063552944 | E57: =D57/C57 -> 0.0018075825 | F57: =$C$29^($B$3-C57) -> 0.27148413 | G57: =F57/'Housekeeper summary'!$E$4 -> 0.60251822
B58: ='Results Workspace'!D81 -> P2.a | C58: ='Results Workspace'!E81 -> 35.849909 | D58: ='Results Workspace'!F81 -> 0.16911125 | E58: =D58/C58 -> 0.0047172017 | F58: =$C$29^($B$3-C58) -> 0.16529245 | G58: =F58/'Housekeeper summary'!$E$4 -> 0.36684176
B59: ='Results Workspace'!D84 -> P3.a | C59: ='Results Workspace'!E84 -> 35.123682 | D59: ='Results Workspace'!F84 -> 0.040781021 | E59: =D59/C59 -> 0.0011610691 | F59: =$C$29^($B$3-C59) -> 0.2784759 | G59: =F59/'Housekeeper summary'!$E$4 -> 0.61803541
B60: ='Results Workspace'!D87 -> P4.a | C60: ='Results Workspace'!E87 -> 35.280927 | D60: ='Results Workspace'!F87 -> 0.16589292 | E60: =D60/C60 -> 0.0047020567 | F60: =$C$29^($B$3-C60) -> 0.2487354 | G60: =F60/'Housekeeper summary'!$E$4 -> 0.55203085
B61: ='Results Workspace'!D90 -> P5.a | C61: ='Results Workspace'!E90 -> 35.588064 | D61: ='Results Workspace'!F90 -> 0.13915819 | E61: =D61/C61 -> 0.0039102489 | F61: =$C$29^($B$3-C61) -> 0.19949471 | G61: =F61/'Housekeeper summary'!$E$4 -> 0.44274852
...

Sheet GABARAP
A1: Standard dilution | B1: Av CT | C1: SD CT | D1: CV CT | E1: Dilution | F1: log dilution
A2: =B33 -> STD 10a | B2: =C33 -> 23.054658 | C2: =D33 -> 0.19535802 | D2: =C2/B2 -> 0.0084736898 | E2: 0.1 | F2: =LOG(E2,10) -> -1
A3: =B34 -> STD 20a | B3: =C34 -> 24.267371 | C3: =D34 -> 0.01429001 | D3: =C3/B3 -> 0.00058885695 | E3: 0.05 | F3: =LOG(E3,10) -> -1.30103
A4: =B35 -> STD 40a | B4: =C35 -> 25.346166 | C4: =D35 -> 0.015427589 | D4: =C4/B4 -> 0.00060867547 | E4: 0.025 | F4: =LOG(E4,10) -> -1.60206
A5: =B36 -> STD 80a | B5: =C36 -> 26.285817 | C5: =D36 -> 0.001698494 | D5: =C5/B5 -> 6.4616365e-05 | E5: 0.0125 | F5: =LOG(E5,10) -> -1.90309
A6: =B37 -> STD 160a | B6: =C37 -> 27.511432 | C6: =D37 -> 0.0046434402 | D6: =C6/B6 -> 0.00016878221 | E6: 0.00625 | F6: =LOG(E6,10) -> -2.20412
A7: =B38 -> STD 320a | B7: =C38 -> 28.530123 | C7: =D38 -> 0.074975163 | D7: =C7/B7 -> 0.0026279299 | E7: 0.003125 | F7: =LOG(E7,10) -> -2.50515
B28: Slope | C28: =SLOPE(B2:B7,F2:F7) -> -3.6113302
B29: Efficiency | C29: =10^(-1/C28) -> 1.8919353
B31: Sample | C31: Av Ct | D31: SD Ct | E31: CV Ct | F31: delta Ct (to STD 20) | G31: deltadelta Ct
B32: ='Results Workspace'!D123 -> Blank 1.a | C32: ='Results Workspace'!E123 -> 40.1 | D32: ='Results Workspace'!F123 -> 0 | E32: =D32/C32 -> 0 | F32: =$C$29^($B$3-C32) -> 4.1290082e-05
B33: ='Results Workspace'!D126 -> STD 10a | C33: ='Results Workspace'!E126 -> 23.054658 | D33: ='Results Workspace'!F126 -> 0.19535802 | E33: =D33/C33 -> 0.0084736898 | F33: =$C$29^($B$3-C33) -> 2.1667455
B34: ='Results Workspace'!D129 -> STD 20a | C34: ='Results Workspace'!E129 -> 24.267371 | D34: ='Results Workspace'!F129 -> 0.01429001 | E34: =D34/C34 -> 0.00058885695 | F34: =$C$29^($B$3-C34) -> 1
B35: ='Results Workspace'!D132 -> STD 40a | C35: ='Results Workspace'!E132 -> 25.346166 | D35: ='Results Workspace'!F132 -> 0.015427589 | E35: =D35/C35 -> 0.00060867547 | F35: =$C$29^($B$3-C35) -> 0.50266092
B36: ='Results Workspace'!D135 -> STD 80a | C36: ='Results Workspace'!E135 -> 26.285817 | D36: ='Results Workspace'!F135 -> 0.001698494 | E36: =D36/C36 -> 6.4616365e-05 | F36: =$C$29^($B$3-C36) -> 0.27610847
B37: ='Results Workspace'!D138 -> STD 160a | C37: ='Results Workspace'!E138 -> 27.511432 | D37: ='Results Workspace'!F138 -> 0.0046434402 | E37: =D37/C37 -> 0.00016878221 | F37: =$C$29^($B$3-C37) -> 0.12638611
B38: ='Results Workspace'!D141 -> STD 320a | C38: ='Results Workspace'!E141 -> 28.530123 | D38: ='Results Workspace'!F141 -> 0.074975163 | E38: =D38/C38 -> 0.0026279299 | F38: =$C$29^($B$3-C38) -> 0.066011166
B39: ='Results Workspace'!D144 -> C1.a | C39: ='Results Workspace'!E144 -> 24.491209 | D39: ='Results Workspace'!F144 -> 0.27484703 | E39: =D39/C39 -> 0.011222273 | F39: =$C$29^($B$3-C39) -> 0.86699777 | G39: =F39/'Housekeeper summary'!$E$4 -> 1.9241713
B40: ='Results Workspace'!D147 -> C2.a | C40: ='Results Workspace'!E147 -> 24.839381 | D40: ='Results Workspace'!F147 -> 0.17527676 | E40: =D40/C40 -> 0.0070564059 | F40: =$C$29^($B$3-C40) -> 0.69439553 | G40: =F40/'Housekeeper summary'!$E$4 -> 1.5411065
B41: ='Results Workspace'!D150 -> C3.a | C41: ='Results Workspace'!E150 -> 25.282127 | D41: ='Results Workspace'!F150 -> 0.12867869 | E41: =D41/C41 -> 0.0050897098 | F41: =$C$29^($B$3-C41) -> 0.52360975 | G41: =F41/'Housekeeper summary'!$E$4 -> 1.1620732
B42: ='Results Workspace'!D153 -> C4.a | C42: ='Results Workspace'!E153 -> 25.529139 | D42: ='Results Workspace'!F153 -> 0.037654556 | E42: =D42/C42 -> 0.0014749638 | F42: =$C$29^($B$3-C42) -> 0.44731017 | G42: =F42/'Housekeeper summary'!$E$4 -> 0.99273771
B43: ='Results Workspace'!D156 -> C5.a | C43: ='Results Workspace'!E156 -> 25.666456 | D43: ='Results Workspace'!F156 -> 0 | E43: =D43/C43 -> 0 | F43: =$C$29^($B$3-C43) -> 0.40981198 | G43: =F43/'Housekeeper summary'!$E$4 -> 0.90951611
B44: ='Results Workspace'!D159 -> C6.a | C44: ='Results Workspace'!E159 -> 25.79085 | D44: ='Results Workspace'!F159 -> 0.13875389 | E44: =D44/C44 -> 0.0053799659 | F44: =$C$29^($B$3-C44) -> 0.37856401 | G44: =F44/'Housekeeper summary'!$E$4 -> 0.84016593
B45: ='Results Workspace'!D162 -> C7.a | C45: ='Results Workspace'!E162 -> 25.514278 | D45: ='Results Workspace'!F162 -> 0.073501587 | E45: =D45/C45 -> 0.0028808021 | F45: =$C$29^($B$3-C45) -> 0.45156851 | G45: =F45/'Housekeeper summary'!$E$4 -> 1.0021884
B46: ='Results Workspace'!D165 -> C8.a | C46: ='Results Workspace'!E165 -> 25.04718 | D46: ='Results Workspace'!F165 -> 0.1341946 | E46: =D46/C46 -> 0.0053576732 | F46: =$C$29^($B$3-C46) -> 0.60822778 | G46: =F46/'Housekeeper summary'!$E$4 -> 1.3498702
B47: ='Results Workspace'!D168 -> C9.a | C47: ='Results Workspace'!E168 -> 24.740263 | D47: ='Results Workspace'!F168 -> 0 | E47: =D47/C47 -> 0 | F47: =$C$29^($B$3-C47) -> 0.73969618 | G47: =F47/'Housekeeper summary'!$E$4 -> 1.6416445
B48: ='Results Workspace'!D171 -> O1.a | C48: ='Results Workspace'!E171 -> 24.95659 | D48: ='Results Workspace'!F171 -> 0.40445241 | E48: =D48/C48 -> 0.016206237 | F48: =$C$29^($B$3-C48) -> 0.64439337 | G48: =F48/'Housekeeper summary'!$E$4 -> 1.4301342
B49: ='Results Workspace'!D174 -> O2.a | C49: ='Results Workspace'!E174 -> 25.753615 | D49: ='Results Workspace'!F174 -> 0.13618445 | E49: =D49/C49 -> 0.005287974 | F49: =$C$29^($B$3-C49) -> 0.38765896 | G49: =F49/'Housekeeper summary'!$E$4 -> 0.8603508
B50: ='Results Workspace'!D177 -> O3.a | C50: ='Results Workspace'!E177 -> 25.23352 | D50: ='Results Workspace'!F177 -> 0.092336995 | E50: =D50/C50 -> 0.003659299 | F50: =$C$29^($B$3-C50) -> 0.54009163 | G50: =F50/'Housekeeper summary'!$E$4 -> 1.1986522
B51: ='Results Workspace'!D180 -> O4.a | C51: ='Results Workspace'!E180 -> 25.370821 | D51: ='Results Workspace'!F180 -> 0.10990143 | E51: =D51/C51 -> 0.0043318042 | F51: =$C$29^($B$3-C51) -> 0.49482075 | G51: =F51/'Housekeeper summary'!$E$4 -> 1.0981803
B52: ='Results Workspace'!D183 -> O5.a | C52: ='Results Workspace'!E183 -> 25.329286 | D52: ='Results Workspace'!F183 -> 0.047654152 | E52: =D52/C52 -> 0.0018813855 | F52: =$C$29^($B$3-C52) -> 0.50810013 | G52: =F52/'Housekeeper summary'!$E$4 -> 1.1276519
B53: ='Results Workspace'!D186 -> O6.a | C53: ='Results Workspace'!E186 -> 25.164757 | D53: ='Results Workspace'!F186 -> 0.039157867 | E53: =D53/C53 -> 0.0015560598 | F53: =$C$29^($B$3-C53) -> 0.56429783 | G53: =F53/'Housekeeper summary'!$E$4 -> 1.2523742
B54: ='Results Workspace'!D189 -> O7.a | C54: ='Results Workspace'!E189 -> 25.298236 | D54: ='Results Workspace'!F189 -> 0.18800748 | E54: =D54/C54 -> 0.0074316438 | F54: =$C$29^($B$3-C54) -> 0.51825928 | G54: =F54/'Housekeeper summary'!$E$4 -> 1.1501986
B55: ='Results Workspace'!D192 -> O8.a | C55: ='Results Workspace'!E192 -> 24.371911 | D55: ='Results Workspace'!F192 -> 0.69711971 | E55: =D55/C55 -> 0.028603408 | F55: =$C$29^($B$3-C55) -> 0.93551842 | G55: =F55/'Housekeeper summary'!$E$4 -> 2.0762425
B56: ='Results Workspace'!D195 -> O9.a | C56: ='Results Workspace'!E195 -> 25.110367 | D56: ='Results Workspace'!F195 -> 0.1108462 | E56: =D56/C56 -> 0.0044143601 | F56: =$C$29^($B$3-C56) -> 0.58421042 | G56: =F56/'Housekeeper summary'!$E$4 -> 1.2965672
B57: ='Results Workspace'!D198 -> P1.a | C57: ='Results Workspace'!E198 -> 25.088261 | D57: ='Results Workspace'!F198 -> 0.13414955 | E57: =D57/C57 -> 0.0053471045 | F57: =$C$29^($B$3-C57) -> 0.59250312 | G57: =F57/'Housekeeper summary'!$E$4 -> 1.3149716
B58: ='Results Workspace'!D201 -> P2.a | C58: ='Results Workspace'!E201 -> 25.360667 | D58: ='Results Workspace'!F201 -> 0.082722942 | E58: =D58/C58 -> 0.0032618599 | F58: =$C$29^($B$3-C58) -> 0.49803474 | G58: =F58/'Housekeeper summary'!$E$4 -> 1.1053133
B59: ='Results Workspace'!D204 -> P3.a | C59: ='Results Workspace'!E204 -> 26.282637 | D59: ='Results Workspace'!F204 -> 0.77967644 | E59: =D59/C59 -> 0.029665077 | F59: =$C$29^($B$3-C59) -> 0.27666895 | G59: =F59/'Housekeeper summary'!$E$4 -> 0.61402516
B60: ='Results Workspace'!D207 -> P4.a | C60: ='Results Workspace'!E207 -> 25.553368 | D60: ='Results Workspace'!F207 -> 0.15148735 | E60: =D60/C60 -> 0.0059282734 | F60: =$C$29^($B$3-C60) -> 0.44045303 | G60: =F60/'Housekeeper summary'!$E$4 -> 0.9775193
B61: ='Results Workspace'!D210 -> P5.a | C61: ='Results Workspace'!E210 -> 25.343601 | D61: ='Results Workspace'!F210 -> 0.0050907135 | E61: =D61/C61 -> 0.0002008678 | F61: =$C$29^($B$3-C61) -> 0.50348348 | G61: =F61/'Housekeeper summary'!$E$4 -> 1.1174059
...

Sheet P62
A1: Standard dilution | B1: Av CT | C1: SD CT | D1: CV CT | E1: Dilution | F1: log dilution
A2: =B33 -> STD 10a | B2: =C33 -> 24.888777 | C2: =D33 -> 0.067589402 | D2: =C2/B2 -> 0.0027156579 | E2: 0.1 | F2: =LOG(E2,10) -> -1
A3: =B34 -> STD 20a | B3: =C34 -> 25.808697 | C3: =D34 -> 0.09993606 | D3: =C3/B3 -> 0.0038721853 | E3: 0.05 | F3: =LOG(E3,10) -> -1.30103
A4: =B35 -> STD 40a | B4: =C35 -> 26.983889 | C4: =D35 -> 0.012155177 | D4: =C4/B4 -> 0.00045046055 | E4: 0.025 | F4: =LOG(E4,10) -> -1.60206
A5: =B36 -> STD 80a | B5: =C36 -> 27.963738 | C5: =D36 -> 0.19560314 | D5: =C5/B5 -> 0.0069948851 | E5: 0.0125 | F5: =LOG(E5,10) -> -1.90309
A6: =B37 -> STD 160a | B6: =C37 -> 29.043431 | C6: =D37 -> 0.030742027 | D6: =C6/B6 -> 0.0010584847 | E6: 0.00625 | F6: =LOG(E6,10) -> -2.20412
A7: =B38 -> STD 320a | B7: =C38 -> 30.318076 | C7: =D38 -> 0.09671876 | D7: =C7/B7 -> 0.0031901351 | E7: 0.003125 | F7: =LOG(E7,10) -> -2.50515
B28: Slope | C28: =SLOPE(B2:B7,F2:F7) -> -3.5905818
B29: Efficiency | C29: =10^(-1/C28) -> 1.8989188
B31: Sample | C31: Av Ct | D31: SD Ct | E31: CV Ct | F31: delta Ct (to STD 20) | G31: deltadelta Ct
B32: ='Results Workspace'!D243 -> Blank 1.a | C32: ='Results Workspace'!E243 -> 40.1 | D32: ='Results Workspace'!F243 -> 0 | E32: =D32/C32 -> 0 | F32: =$C$29^($B$3-C32) -> 0.00010466001
B33: ='Results Workspace'!D246 -> STD 10a | C33: ='Results Workspace'!E246 -> 24.888777 | D33: ='Results Workspace'!F246 -> 0.067589402 | E33: =D33/C33 -> 0.0027156579 | F33: =$C$29^($B$3-C33) -> 1.8038639
B34: ='Results Workspace'!D249 -> STD 20a | C34: ='Results Workspace'!E249 -> 25.808697 | D34: ='Results Workspace'!F249 -> 0.09993606 | E34: =D34/C34 -> 0.0038721853 | F34: =$C$29^($B$3-C34) -> 1
B35: ='Results Workspace'!D252 -> STD 40a | C35: ='Results Workspace'!E252 -> 26.983889 | D35: ='Results Workspace'!F252 -> 0.012155177 | E35: =D35/C35 -> 0.00045046055 | F35: =$C$29^($B$3-C35) -> 0.47065396
B36: ='Results Workspace'!D255 -> STD 80a | C36: ='Results Workspace'!E255 -> 27.963738 | D36: ='Results Workspace'!F255 -> 0.19560314 | E36: =D36/C36 -> 0.0069948851 | F36: =$C$29^($B$3-C36) -> 0.25107725
B37: ='Results Workspace'!D258 -> STD 160a | C37: ='Results Workspace'!E258 -> 29.043431 | D37: ='Results Workspace'!F258 -> 0.030742027 | E37: =D37/C37 -> 0.0010584847 | F37: =$C$29^($B$3-C37) -> 0.12563366
B38: ='Results Workspace'!D261 -> STD 320a | C38: ='Results Workspace'!E261 -> 30.318076 | D38: ='Results Workspace'!F261 -> 0.09671876 | E38: =D38/C38 -> 0.0031901351 | F38: =$C$29^($B$3-C38) -> 0.055476503
B39: ='Results Workspace'!D264 -> C1.a | C39: ='Results Workspace'!E264 -> 26.974548 | D39: ='Results Workspace'!F264 -> 0.053923994 | E39: =D39/C39 -> 0.0019990694 | F39: =$C$29^($B$3-C39) -> 0.47348173 | G39: =F39/'Housekeeper summary'!$E$4 -> 1.0508215
B40: ='Results Workspace'!D267 -> C2.a | C40: ='Results Workspace'!E267 -> 27.27474 | D40: ='Results Workspace'!F267 -> 0.053103723 | E40: =D40/C40 -> 0.0019469929 | F40: =$C$29^($B$3-C40) -> 0.39056909 | G40: =F40/'Housekeeper summary'!$E$4 -> 0.8668094
B41: ='Results Workspace'!D270 -> C3.a | C41: ='Results Workspace'!E270 -> 27.011938 | D41: ='Results Workspace'!F270 -> 0.090716807 | E41: =D41/C41 -> 0.0033583968 | F41: =$C$29^($B$3-C41) -> 0.46226367 | G41: =F41/'Housekeeper summary'!$E$4 -> 1.0259247
B42: ='Results Workspace'!D273 -> C4.a | C42: ='Results Workspace'!E273 -> 26.792233 | D42: ='Results Workspace'!F273 -> 0.017758114 | E42: =D42/C42 -> 0.00066280828 | F42: =$C$29^($B$3-C42) -> 0.53220506 | G42: =F42/'Housekeeper summary'!$E$4 -> 1.1811491
B43: ='Results Workspace'!D276 -> C5.a | C43: ='Results Workspace'!E276 -> 26.783548 | D43: ='Results Workspace'!F276 -> 0.05120098 | E43: =D43/C43 -> 0.0019116579 | F43: =$C$29^($B$3-C43) -> 0.53517762 | G43: =F43/'Housekeeper summary'!$E$4 -> 1.1877463
B44: ='Results Workspace'!D279 -> C6.a | C44: ='Results Workspace'!E279 -> 26.665009 | D44: ='Results Workspace'!F279 -> 0.0081606998 | E44: =D44/C44 -> 0.00030604527 | F44: =$C$29^($B$3-C44) -> 0.57744664 | G44: =F44/'Housekeeper summary'!$E$4 -> 1.2815561
B45: ='Results Workspace'!D282 -> C7.a | C45: ='Results Workspace'!E282 -> 26.776264 | D45: ='Results Workspace'!F282 -> 0.094322716 | E45: =D45/C45 -> 0.0035226242 | F45: =$C$29^($B$3-C45) -> 0.53768318 | G45: =F45/'Housekeeper summary'!$E$4 -> 1.193307
B46: ='Results Workspace'!D285 -> C8.a | C46: ='Results Workspace'!E285 -> 26.334227 | D46: ='Results Workspace'!F285 -> 0.019914829 | E46: =D46/C46 -> 0.00075623364 | F46: =$C$29^($B$3-C46) -> 0.71389867 | G46: =F46/'Housekeeper summary'!$E$4 -> 1.5843908
B47: ='Results Workspace'!D288 -> C9.a | C47: ='Results Workspace'!E288 -> 26.870728 | D47: ='Results Workspace'!F288 -> 0.088153839 | E47: =D47/C47 -> 0.0032806644 | F47: =$C$29^($B$3-C47) -> 0.50607841 | G47: =F47/'Housekeeper summary'!$E$4 -> 1.123165
B48: ='Results Workspace'!D291 -> O1.a | C48: ='Results Workspace'!E291 -> 27.055234 | D48: ='Results Workspace'!F291 -> 0.11392605 | E48: =D48/C48 -> 0.0042108693 | F48: =$C$29^($B$3-C48) -> 0.44960556 | G48: =F48/'Housekeeper summary'!$E$4 -> 0.99783199
B49: ='Results Workspace'!D294 -> O2.a | C49: ='Results Workspace'!E294 -> 26.98067 | D49: ='Results Workspace'!F294 -> 0.027719258 | E49: =D49/C49 -> 0.0010273747 | F49: =$C$29^($B$3-C49) -> 0.47162653 | G49: =F49/'Housekeeper summary'!$E$4 -> 1.0467042
B50: ='Results Workspace'!D297 -> O3.a | C50: ='Results Workspace'!E297 -> 26.553326 | D50: ='Results Workspace'!F297 -> 0.04173598 | E50: =D50/C50 -> 0.0015717798 | F50: =$C$29^($B$3-C50) -> 0.62032068 | G50: =F50/'Housekeeper summary'!$E$4 -> 1.3767085
B51: ='Results Workspace'!D300 -> O4.a | C51: ='Results Workspace'!E300 -> 26.565551 | D51: ='Results Workspace'!F300 -> 0.13014213 | E51: =D51/C51 -> 0.0048989059 | F51: =$C$29^($B$3-C51) -> 0.61547638 | G51: =F51/'Housekeeper summary'!$E$4 -> 1.3659573
B52: ='Results Workspace'!D303 -> O5.a | C52: ='Results Workspace'!E303 -> 26.859351 | D52: ='Results Workspace'!F303 -> 0.034039532 | E52: =D52/C52 -> 0.0012673252 | F52: =$C$29^($B$3-C52) -> 0.5097841 | G52: =F52/'Housekeeper summary'!$E$4 -> 1.1313892
B53: ='Results Workspace'!D306 -> O6.a | C53: ='Results Workspace'!E306 -> 26.881657 | D53: ='Results Workspace'!F306 -> 0.079067362 | E53: =D53/C53 -> 0.0029413128 | F53: =$C$29^($B$3-C53) -> 0.50254366 | G53: =F53/'Housekeeper summary'!$E$4 -> 1.1153201
B54: ='Results Workspace'!D309 -> O7.a | C54: ='Results Workspace'!E309 -> 27.135417 | D54: ='Results Workspace'!F309 -> 0.050572999 | E54: =D54/C54 -> 0.0018637266 | F54: =$C$29^($B$3-C54) -> 0.42707111 | G54: =F54/'Housekeeper summary'!$E$4 -> 0.94782014
B55: ='Results Workspace'!D312 -> O8.a | C55: ='Results Workspace'!E312 -> 26.718585 | D55: ='Results Workspace'!F312 -> 0.036968551 | E55: =D55/C55 -> 0.0013836269 | F55: =$C$29^($B$3-C55) -> 0.55794394 | G55: =F55/'Housekeeper summary'!$E$4 -> 1.2382727
B56: ='Results Workspace'!D315 -> O9.a | C56: ='Results Workspace'!E315 -> 26.898149 | D56: ='Results Workspace'!F315 -> 0.052696397 | E56: =D56/C56 -> 0.0019591087 | F56: =$C$29^($B$3-C56) -> 0.49725667 | G56: =F56/'Housekeeper summary'!$E$4 -> 1.1035865
B57: ='Results Workspace'!D318 -> P1.a | C57: ='Results Workspace'!E318 -> 26.966519 | D57: ='Results Workspace'!F318 -> 0.064721951 | E57: =D57/C57 -> 0.0024000855 | F57: =$C$29^($B$3-C57) -> 0.47592581 | G57: =F57/'Housekeeper summary'!$E$4 -> 1.0562458
B58: ='Results Workspace'!D321 -> P2.a | C58: ='Results Workspace'!E321 -> 26.664351 | D58: ='Results Workspace'!F321 -> 0.090401846 | E58: =D58/C58 -> 0.0033903636 | F58: =$C$29^($B$3-C58) -> 0.57769014 | G58: =F58/'Housekeeper summary'!$E$4 -> 1.2820964
B59: ='Results Workspace'!D324 -> P3.a | C59: ='Results Workspace'!E324 -> 26.964761 | D59: ='Results Workspace'!F324 -> 0.15264073 | E59: =D59/C59 -> 0.0056607486 | F59: =$C$29^($B$3-C59) -> 0.47646265 | G59: =F59/'Housekeeper summary'!$E$4 -> 1.0574372
B60: ='Results Workspace'!D327 -> P4.a | C60: ='Results Workspace'!E327 -> 26.99005 | D60: ='Results Workspace'!F327 -> 0.076334362 | E60: =D60/C60 -> 0.0028282409 | F60: =$C$29^($B$3-C60) -> 0.46879799 | G60: =F60/'Housekeeper summary'!$E$4 -> 1.0404267
B61: ='Results Workspace'!D330 -> P5.a | C61: ='Results Workspace'!E330 -> 26.72181 | D61: ='Results Workspace'!F330 -> 0.019005358 | E61: =D61/C61 -> 0.00071123018 | F61: =$C$29^($B$3-C61) -> 0.5567911 | G61: =F61/'Housekeeper summary'!$E$4 -> 1.2357142
...

Sheet Housekeeper summary
B3: B2M | C3: HMBS | D3: YWHA2 | E3: geometric mean
A4: C1.a | B4: 0.42639273 | C4: 0.35252626 | D4: 0.60858536 | E4: =10^((LOG(B4,10)+LOG(C4,10)+LOG(D4,10))/COUNT(B4:D4)) -> 0.45058243
A5: C2.a | B5: 0.3151255 | C5: 0.44111181 | D5: 0.52650694 | E5: =10^((LOG(B5,10)+LOG(C5,10)+LOG(D5,10))/COUNT(B5:D5)) -> 0.41829125
A6: C3.a | B6: 0.45273714 | C6: 0.44945493 | D6: 0.56496675 | E6: =10^((LOG(B6,10)+LOG(C6,10)+LOG(D6,10))/COUNT(B6:D6)) -> 0.48624116
A7: C4.a | B7: 0.38295018 | C7: 0.46151957 | D7: 0.54473383 | E7: =10^((LOG(B7,10)+LOG(C7,10)+LOG(D7,10))/COUNT(B7:D7)) -> 0.45832363
A8: C5.a | B8: 0.42833088 | C8: 0.42335788 | D8: 0.53523552 | E8: =10^((LOG(B8,10)+LOG(C8,10)+LOG(D8,10))/COUNT(B8:D8)) -> 0.45956187
A9: C6.a | B9: 0.35794 | C9: 0.38296224 | D9: 0.57185694 | E9: =10^((LOG(B9,10)+LOG(C9,10)+LOG(D9,10))/COUNT(B9:D9)) -> 0.42797447
A10: C7.a | B10: 0.37340238 | C10: 0.48233808 | D10: 0.51357492 | E10: =10^((LOG(B10,10)+LOG(C10,10)+LOG(D10,10))/COUNT(B10:D10)) -> 0.45224886
A11: C8.a | B11: 0.35503258 | C11: 0.61615231 | D11: 0.73880119 | E11: =10^((LOG(B11,10)+LOG(C11,10)+LOG(D11,10))/COUNT(B11:D11)) -> 0.54470491
A12: C9.a | B12: 0.41592619 | C12: 0.62216434 | D12: 0.63444703 | E12: =10^((LOG(B12,10)+LOG(C12,10)+LOG(D12,10))/COUNT(B12:D12)) -> 0.54756908
A13: O1.a | B13: 0.45842475 | C13: 0.4345604 | D13: 0.55125833 | E13: =10^((LOG(B13,10)+LOG(C13,10)+LOG(D13,10))/COUNT(B13:D13)) -> 0.47887753
A14: O2.a | B14: 0.43374488 | C14: 0.32980761 | D14: 0.48402583 | E14: =10^((LOG(B14,10)+LOG(C14,10)+LOG(D14,10))/COUNT(B14:D14)) -> 0.41063364
A15: O3.a | B15: 0.40114007 | C15: 0.42898411 | D15: 0.595409 | E15: =10^((LOG(B15,10)+LOG(C15,10)+LOG(D15,10))/COUNT(B15:D15)) -> 0.46793358
... A30: P9.a | B30: 0.24389984 | C30: 0.56725696 | D30: 0.75712784 | E30: =10^((LOG(B30,10)+LOG(C30,10)+LOG(D30,10))/COUNT(B30:D30)) -> 0.47139704
